data/lithium_ticks_sample_preview.csv
timestamp_ms,symbol,price,size,side
4,ALB,118.745,27.1975,B
19,ALB,118.745,78.4994,B
28,ALB,118.752,38.2609,S
39,SQM,52.2938,51.3121,S
54,SQM,52.2993,34.309,B
55,SQM,52.3005,44.0843,B
67,SQM,52.3028,37.189,B
67,PLS,3.4241,64.9479,B
78,ALB,118.75,79.9226,S
79,SQM,52.3063,142.079,S
80,SQM,52.3061,95.5559,S
81,SQM,52.2983,65.796,S
85,SQM,52.2908,38.3891,B
98,SQM,52.2769,99.5287,B
100,ALB,118.76,62.1384,B
106,ALB,118.765,74.9164,B
109,ALB,118.755,73.2247,S
110,SQM,52.2801,98.9201,S
117,PLS,3.42939,32.3976,B
121,PLS,3.43069,60.7997,B
122,PLS,3.42931,66.6124,S
131,SQM,52.2804,124.075,S
153,SQM,52.286,78.3159,S
161,SQM,52.2724,76.622,B
166,ALB,118.762,54.7179,S
173,PLS,3.42245,24.1403,S
178,ALB,118.751,66.3447,S
184,SQM,52.2536,61.5938,S
187,PLS,3.4203,87.9667,B
187,ALB,118.752,26.0121,B
196,PLS,3.42299,55.6946,B
196,ALB,118.746,47.6651,S
219,PLS,3.41771,100.023,S
231,SQM,52.2525,101.165,B
246,ALB,118.731,73.0224,B
253,SQM,52.2435,93.1993,B
254,PLS,3.4252,46.1965,B
263,ALB,118.728,49.3641,S
263,PLS,3.43073,20.9557,S
277,ALB,118.716,61.3227,S
278,ALB,118.706,53.2035,B
287,PLS,3.42863,82.0069,S
314,ALB,118.7,25.05,S
316,ALB,118.681,62.8167,S
320,ALB,118.679,106.073,S
321,PLS,3.43507,60.878,S
342,SQM,52.2509,64.4859,B
355,ALB,118.674,29.2546,B
356,SQM,52.2556,88.2865,B
376,SQM,52.2598,60.0495,S
378,PLS,3.42691,51.7683,B
401,ALB,118.657,53.9833,S
415,ALB,118.667,58.0803,S
426,ALB,118.653,184.932,B
447,SQM,52.252,65.396,S
462,PLS,3.42162,67.1355,B
471,SQM,52.2488,27.1297,B
497,ALB,118.644,46.3884,S
506,PLS,3.42286,11.1632,B
524,SQM,52.2427,35.4882,B
529,PLS,3.42406,71.0264,B
536,PLS,3.41903,165.59,S
537,ALB,118.631,43.4816,S
555,ALB,118.638,135.827,S
557,ALB,118.656,23.8337,B
573,ALB,118.65,75.9872,B
574,ALB,118.65,29.3856,S
583,SQM,52.2296,32.8012,B
587,SQM,52.2381,50.5686,S
594,SQM,52.233,102.706,B
595,SQM,52.2263,32.2236,B
603,ALB,118.631,115.834,B
622,PLS,3.4206,51.7482,S
626,SQM,52.2255,93.0277,B
644,SQM,52.221,101.078,B
646,SQM,52.2144,54.0041,S
652,ALB,118.635,51.8307,S
658,SQM,52.2011,65.9643,S
665,ALB,118.634,68.2578,S
672,ALB,118.64,63.9993,S
675,SQM,52.2055,33.9288,B
678,ALB,118.649,69.1278,B
679,ALB,118.642,51.5649,S
686,PLS,3.42005,49.6068,B
694,ALB,118.647,33.7555,S
704,ALB,118.647,68.9484,S
706,PLS,3.41845,56.2299,S
712,PLS,3.41084,70.9238,B
716,SQM,52.2133,15.8814,B
726,PLS,3.3987,31.6307,S
729,PLS,3.39518,50.742,B
744,PLS,3.4001,62.3058,B
761,SQM,52.2221,66.5655,B
765,ALB,118.638,68.9184,B
767,SQM,52.2338,65.9492,B
772,ALB,118.629,44.0866,B
774,SQM,52.2353,32.0592,B
792,ALB,118.636,43.6433,S
809,ALB,118.631,20.7281,B
820,SQM,52.2453,48.7468,S
823,PLS,3.39699,26.021,S
829,ALB,118.625,73.425,B
833,PLS,3.3957,64.7063,B
843,ALB,118.607,36.8363,B
849,ALB,118.599,27.5745,B
864,ALB,118.597,30.8401,B
867,SQM,52.2632,31.596,B
867,PLS,3.39666,17.6439,B
869,PLS,3.39615,50.5175,S
875,ALB,118.598,75.4402,S
876,ALB,118.602,72.379,B
883,SQM,52.2717,45.0755,B
887,SQM,52.2644,21.2581,S
899,PLS,3.38889,101.627,S
904,SQM,52.2778,25.8123,S
916,PLS,3.38672,33.5137,S
921,ALB,118.588,89.738,S
939,ALB,118.579,45.3751,S
977,ALB,118.55,76.2749,B
992,PLS,3.3908,47.233,S
997,ALB,118.55,89.5286,S
1000,SQM,52.2775,27.8892,B
1003,PLS,3.39987,85.6248,B
1023,ALB,118.548,46.7675,S
1024,ALB,118.547,30.0119,B
1026,ALB,118.545,100.087,S
1027,SQM,52.2866,24.8932,S
1048,SQM,52.2885,70.3363,B
1065,PLS,3.4058,99.3803,B
1092,PLS,3.40757,24.0876,B
1124,SQM,52.2884,118.305,B
1149,PLS,3.41937,86.967,B
1158,ALB,118.534,163.779,S
1166,ALB,118.522,68.5141,B
1171,ALB,118.546,70.218,S
1173,ALB,118.543,55.6293,B
1180,ALB,118.545,42.9642,B
1182,ALB,118.549,78.6513,S
1188,PLS,3.41695,25.4157,B
1189,PLS,3.4164,134.83,S
1191,ALB,118.55,58.4233,B
1214,ALB,118.553,97.0011,B
1222,SQM,52.2837,22.7705,B
1227,PLS,3.41701,74.2309,B
1232,ALB,118.539,54.1822,S
1233,SQM,52.2815,109.377,B
1240,SQM,52.2697,37.9364,S
1260,SQM,52.2594,42.2986,B
1283,SQM,52.2644,51.2201,B
1288,ALB,118.537,67.9644,B
1303,PLS,3.41655,73.3442,S
1334,PLS,3.41269,52.1562,B
1335,ALB,118.547,43.5051,B
1335,PLS,3.40583,74.2603,B
1337,SQM,52.2525,148.439,B
1364,SQM,52.248,58.5835,S
1371,SQM,52.2388,21.3242,B
1380,SQM,52.2466,50.6218,S
1385,SQM,52.2412,67.4345,B
1388,SQM,52.2363,83.0965,B
1393,SQM,52.2353,38.9116,B
1394,SQM,52.2436,72.8898,B
1395,PLS,3.40143,90.554,B
1402,PLS,3.4006,66.4181,B
1410,ALB,118.532,26.9813,B
1412,SQM,52.2424,43.3167,S
1413,ALB,118.533,44.5286,S
1413,SQM,52.2447,47.8608,B
1415,SQM,52.2329,94.4809,B
1430,SQM,52.2343,70.9734,S
1431,SQM,52.2301,56.9448,S
1436,PLS,3.39774,22.8867,B
1439,ALB,118.527,48.0382,B
1440,PLS,3.3945,65.2066,S
1441,ALB,118.533,41.7644,S
1449,PLS,3.3918,39.6569,S
1459,SQM,52.2315,86.7574,S
1460,PLS,3.38708,65.5856,B
1464,PLS,3.38524,48.7233,B
1469,ALB,118.537,80.6845,S
1471,ALB,118.522,53.8127,S
1499,SQM,52.2372,60.4696,S
1503,PLS,3.38682,99.6876,B
1510,ALB,118.526,77.7752,B
1523,ALB,118.503,33.7023,S
1524,ALB,118.503,107.723,S
1525,PLS,3.38414,80.7618,B
1529,PLS,3.38971,48.6489,B
1540,SQM,52.2486,73.3805,S
1548,SQM,52.253,51.6397,B
1551,ALB,118.489,33.8804,B
1566,PLS,3.38596,120.619,S
1572,SQM,52.2401,103.644,B
1579,SQM,52.2524,105.978,B
1588,ALB,118.486,48.8469,S
1590,ALB,118.478,46.3858,S
1595,ALB,118.47,25.8714,S
1615,ALB,118.461,27.5003,S
1621,ALB,118.464,52.9959,B
1631,PLS,3.38876,75.5489,B
1647,SQM,52.2474,109.375,S
1650,ALB,118.458,29.5571,B
1658,ALB,118.469,41.0531,B
1665,ALB,118.468,90.4268,S
1666,ALB,118.477,150.425,B
1668,SQM,52.2465,66.1153,S
1668,ALB,118.474,55.9571,S
1671,PLS,3.38475,38.9147,S
1675,SQM,52.2488,31.325,S
1683,ALB,118.471,25.028,S
1688,ALB,118.459,59.2952,S
1689,PLS,3.3819,32.0084,S
1698,ALB,118.466,29.0748,S
1708,SQM,52.2592,17.6886,B
1723,PLS,3.38144,72.9365,S
1725,SQM,52.2508,89.3009,B
1748,PLS,3.38632,181.748,S
1768,PLS,3.39289,69.1593,S
1780,ALB,118.467,37.9564,S
1788,PLS,3.39278,51.9675,B
1803,SQM,52.2353,10.1549,S
1805,SQM,52.2273,61.8466,S
1812,ALB,118.471,33.0401,S
1814,PLS,3.39396,90.0289,B
1854,PLS,3.39416,86.0488,B
1866,ALB,118.462,138.94,B
1871,SQM,52.2293,126.172,S
1879,ALB,118.474,91.1418,B
1888,ALB,118.469,75.431,B
1898,ALB,118.462,126.358,S
1900,ALB,118.474,51.2663,S
1901,SQM,52.2301,45.0718,S
1912,ALB,118.475,76.1292,B
1913,SQM,52.231,30.3239,S
1919,SQM,52.2334,49.719,S
1920,ALB,118.492,78.8332,B
1923,PLS,3.39404,60.0305,S
1924,ALB,118.488,29.1235,S
1931,PLS,3.38807,59.6127,B
1941,SQM,52.244,138.433,B
1942,PLS,3.3917,28.9824,S
1950,PLS,3.39193,142.576,B
1952,SQM,52.2523,44.2082,B
1964,SQM,52.2421,80.1716,S
2007,SQM,52.2535,15.9651,B
2009,SQM,52.2619,47.315,S
2015,ALB,118.474,26.4329,B
2059,ALB,118.488,68.8458,S
2065,PLS,3.39666,79.4169,B
2066,PLS,3.40547,19.2357,B
2084,ALB,118.472,60.9154,B
2095,ALB,118.457,30.7368,B
2098,ALB,118.453,51.9131,B
2104,SQM,52.2679,32.0353,B
2105,SQM,52.2489,33.6645,B
2120,PLS,3.41676,76.0368,S
2129,PLS,3.40892,63.5498,S
2131,ALB,118.463,53.7116,S
2134,ALB,118.467,59.1712,B
2141,ALB,118.48,23.5643,S
2193,ALB,118.478,24.3068,B
2194,ALB,118.501,22.6342,S
2200,PLS,3.41095,88.7979,B
2201,PLS,3.40833,50.2755,S
2210,ALB,118.517,84.1945,S
2233,ALB,118.514,58.0804,B
2239,ALB,118.503,18.478,B
2242,SQM,52.2642,40.4351,S
2244,SQM,52.2552,32.4459,B
2256,SQM,52.2464,23.8061,B
2257,SQM,52.2389,25.8859,B
2264,SQM,52.2453,91.7052,S
2264,ALB,118.482,85.2572,S
2268,SQM,52.2441,117.161,B
2274,ALB,118.478,111.339,B
2275,ALB,118.488,84.3358,S
2290,ALB,118.485,60.9022,S
2322,PLS,3.4073,34.896,S
2373,SQM,52.2373,101.115,B
2373,ALB,118.479,61.5228,S
2374,SQM,52.2511,42.8546,B
2377,ALB,118.469,54.8982,S
2388,ALB,118.463,46.0548,B
2393,SQM,52.253,81.9761,S
2404,SQM,52.2562,36.9831,B
2405,PLS,3.41307,75.8905,S
2410,ALB,118.461,47.9214,S
2412,SQM,52.2536,44.1231,S
2415,PLS,3.40822,34.2986,B
2425,ALB,118.457,43.1386,B
2428,SQM,52.2569,41.0724,S
2432,ALB,118.448,48.1528,S
2450,PLS,3.40796,79.6746,B
2459,PLS,3.40533,56.5917,S
2499,ALB,118.466,34.209,S
2514,SQM,52.2823,100.124,B
2515,ALB,118.471,37.9819,S
2521,ALB,118.496,20.0032,S
2554,SQM,52.2767,55.9684,S
2577,SQM,52.2972,128.934,B
2586,ALB,118.477,74.1551,S
2590,ALB,118.466,50.8872,S
2591,SQM,52.3055,21.2862,S
